<?xml version='1.0'?>
<sdf version='1.4'>
  <model name="octagon">

    <link name="base">
      <pose>0 0 0 0 0 0</pose>
      <inertial>
        <mass>0.01</mass>
      </inertial>
    </link>
    <link name="link_prismatic_x">
      <pose>0 0 0 0 0 0</pose>
      <inertial>
        <mass>0.01</mass>
      </inertial>
    </link>
    <link name="link_prismatic_y">
      <pose>0 0 0 0 0 0</pose>
      <inertial>
        <mass>0.01</mass>
      </inertial>
    </link>
    <link name="link_prismatic_z">
      <pose>0 0 0 0 0 0</pose>
      <inertial>
        <mass>0.01</mass>
      </inertial>
    </link>
    <link name="link_revolute_x">
      <pose>0 0 0 0 0 0</pose>
      <inertial>
        <mass>0.01</mass>
      </inertial>
    </link>
    <link name="link_revolute_y">
      <pose>0 0 0 0 0 0</pose>
      <inertial>
        <mass>0.01</mass>
      </inertial>
    </link>
    <link name="link_revolute_z">
      <pose>0 0 0 0 0 0</pose>
      <inertial>
        <mass>0.01</mass>
      </inertial>
    </link>

    <joint name="prismatic_x" type="prismatic">
      <parent>base</parent>
      <child>link_prismatic_x</child>
      <axis>
        <xyz>1 0 0</xyz>
        <limit>
          <lower>0</lower>
          <upper>4.5</upper>
        </limit>
      </axis>
    </joint>
    <joint name="prismatic_y" type="prismatic">
      <parent>link_prismatic_x</parent>
      <child>link_prismatic_y</child>
      <axis>
        <xyz>0 1 0</xyz>
        <limit>
          <lower>0</lower>
          <upper>4.5</upper>
        </limit>
      </axis>
    </joint>
    <joint name="prismatic_z" type="prismatic">
      <parent>link_prismatic_y</parent>
      <child>link_prismatic_z</child>
      <axis>
        <xyz>0 0 1</xyz>
        <limit>
          <lower>0</lower>
          <upper>0.3</upper>
        </limit>
      </axis>
    </joint>

    <joint name="revolute_x" type="continuous">
      <parent>link_prismatic_z</parent>
      <child>link_revolute_x</child>
      <axis>
        <xyz>1 0 0</xyz>
      </axis>
    </joint>
    <joint name="revolute_y" type="continuous">
      <parent>link_revolute_x</parent>
      <child>link_revolute_y</child>
      <axis>
        <xyz>0 1 0</xyz>
      </axis>
    </joint>
    <joint name="revolute_z" type="continuous">
      <parent>link_revolute_y</parent>
      <child>link_revolute_z</child>
      <axis>
        <xyz>0 0 1</xyz>
      </axis>
    </joint>

    <joint name="connector" type="fixed">
      <parent>link_revolute_z</parent>
      <child>thing</child>
    </joint>

    <link name='thing'>
      <pose>0 0 0 0 -1.57079633 0</pose>
      <inertial>
        <mass>1.0</mass>
      </inertial>
      <collision name='collision'>
        <geometry>
          <mesh>
            <scale>1 1 1</scale>
            <uri>package://symmetries/models/prisms/octagon_prism.obj</uri>
          </mesh>
        </geometry>
      </collision>
      <visual name='visual'>
        <geometry>
          <mesh>
            <scale>1 1 1</scale>
            <uri>package://symmetries/models/prisms/octagon_prism.obj</uri>
          </mesh>
        </geometry>
      </visual>
    </link>

  </model>
</sdf>